Internal Server Error: /cart/
Traceback (most recent call last):
  File "D:\Desktop\flexy_tuta\flexyweb\senv\lib\site-packages\django\core\handlers\exception.py", line 47, in inner
    response = get_response(request)
  File "D:\Desktop\flexy_tuta\flexyweb\senv\lib\site-packages\django\core\handlers\base.py", line 181, in _get_response
    response = wrapped_callback(request, *callback_args, **callback_kwargs)
  File "D:\Desktop\flexy_tuta\flexyweb\senv\lib\site-packages\django\contrib\auth\decorators.py", line 21, in _wrapped_view
    return view_func(request, *args, **kwargs)
  File "D:\Desktop\flexy_tuta\flexyweb\cart\views.py", line 220, in cart
    return render(request, "cart/cart.html", context)
  File "D:\Desktop\flexy_tuta\flexyweb\senv\lib\site-packages\django\shortcuts.py", line 19, in render
    content = loader.render_to_string(template_name, context, request, using=using)
  File "D:\Desktop\flexy_tuta\flexyweb\senv\lib\site-packages\django\template\loader.py", line 62, in render_to_string
    return template.render(context, request)
  File "D:\Desktop\flexy_tuta\flexyweb\senv\lib\site-packages\django\template\backends\django.py", line 61, in render
    return self.template.render(context)
  File "D:\Desktop\flexy_tuta\flexyweb\senv\lib\site-packages\django\template\base.py", line 174, in render
    with context.bind_template(self):
  File "C:\Users\Crn96\AppData\Local\Programs\Python\Python39\lib\contextlib.py", line 117, in __enter__
    return next(self.gen)
  File "D:\Desktop\flexy_tuta\flexyweb\senv\lib\site-packages\django\template\context.py", line 240, in bind_template
    processors = (template.engine.template_context_processors +
  File "D:\Desktop\flexy_tuta\flexyweb\senv\lib\site-packages\django\utils\functional.py", line 48, in __get__
    res = instance.__dict__[self.name] = self.func(instance)
  File "D:\Desktop\flexy_tuta\flexyweb\senv\lib\site-packages\django\template\engine.py", line 105, in template_context_processors
    return tuple(import_string(path) for path in context_processors)
  File "D:\Desktop\flexy_tuta\flexyweb\senv\lib\site-packages\django\template\engine.py", line 105, in <genexpr>
    return tuple(import_string(path) for path in context_processors)
  File "D:\Desktop\flexy_tuta\flexyweb\senv\lib\site-packages\django\utils\module_loading.py", line 30, in import_string
    return cached_import(module_path, class_name)
  File "D:\Desktop\flexy_tuta\flexyweb\senv\lib\site-packages\django\utils\module_loading.py", line 15, in cached_import
    import_module(module_path)
  File "C:\Users\Crn96\AppData\Local\Programs\Python\Python39\lib\importlib\__init__.py", line 127, in import_module
    return _bootstrap._gcd_import(name[level:], package, level)
  File "<frozen importlib._bootstrap>", line 1030, in _gcd_import
  File "<frozen importlib._bootstrap>", line 1007, in _find_and_load
  File "<frozen importlib._bootstrap>", line 984, in _find_and_load_unlocked
ModuleNotFoundError: No module named 'my_auth.context_processors'
"GET /cart/ HTTP/1.1" 500 143115
Internal Server Error: /cart/
Traceback (most recent call last):
  File "D:\Desktop\flexy_tuta\flexyweb\senv\lib\site-packages\django\core\handlers\exception.py", line 47, in inner
    response = get_response(request)
  File "D:\Desktop\flexy_tuta\flexyweb\senv\lib\site-packages\django\core\handlers\base.py", line 181, in _get_response
    response = wrapped_callback(request, *callback_args, **callback_kwargs)
  File "D:\Desktop\flexy_tuta\flexyweb\senv\lib\site-packages\django\contrib\auth\decorators.py", line 21, in _wrapped_view
    return view_func(request, *args, **kwargs)
  File "D:\Desktop\flexy_tuta\flexyweb\cart\views.py", line 220, in cart
    return render(request, "cart/cart.html", context)
  File "D:\Desktop\flexy_tuta\flexyweb\senv\lib\site-packages\django\shortcuts.py", line 19, in render
    content = loader.render_to_string(template_name, context, request, using=using)
  File "D:\Desktop\flexy_tuta\flexyweb\senv\lib\site-packages\django\template\loader.py", line 62, in render_to_string
    return template.render(context, request)
  File "D:\Desktop\flexy_tuta\flexyweb\senv\lib\site-packages\django\template\backends\django.py", line 61, in render
    return self.template.render(context)
  File "D:\Desktop\flexy_tuta\flexyweb\senv\lib\site-packages\django\template\base.py", line 174, in render
    with context.bind_template(self):
  File "C:\Users\Crn96\AppData\Local\Programs\Python\Python39\lib\contextlib.py", line 117, in __enter__
    return next(self.gen)
  File "D:\Desktop\flexy_tuta\flexyweb\senv\lib\site-packages\django\template\context.py", line 240, in bind_template
    processors = (template.engine.template_context_processors +
  File "D:\Desktop\flexy_tuta\flexyweb\senv\lib\site-packages\django\utils\functional.py", line 48, in __get__
    res = instance.__dict__[self.name] = self.func(instance)
  File "D:\Desktop\flexy_tuta\flexyweb\senv\lib\site-packages\django\template\engine.py", line 105, in template_context_processors
    return tuple(import_string(path) for path in context_processors)
  File "D:\Desktop\flexy_tuta\flexyweb\senv\lib\site-packages\django\template\engine.py", line 105, in <genexpr>
    return tuple(import_string(path) for path in context_processors)
  File "D:\Desktop\flexy_tuta\flexyweb\senv\lib\site-packages\django\utils\module_loading.py", line 30, in import_string
    return cached_import(module_path, class_name)
  File "D:\Desktop\flexy_tuta\flexyweb\senv\lib\site-packages\django\utils\module_loading.py", line 15, in cached_import
    import_module(module_path)
  File "C:\Users\Crn96\AppData\Local\Programs\Python\Python39\lib\importlib\__init__.py", line 127, in import_module
    return _bootstrap._gcd_import(name[level:], package, level)
  File "<frozen importlib._bootstrap>", line 1030, in _gcd_import
  File "<frozen importlib._bootstrap>", line 1007, in _find_and_load
  File "<frozen importlib._bootstrap>", line 984, in _find_and_load_unlocked
ModuleNotFoundError: No module named 'my_auth.context_processors'
"GET /cart/ HTTP/1.1" 500 142941
Internal Server Error: /pay/payfast/
Traceback (most recent call last):
  File "D:\Desktop\flexy_tuta\flexyweb\senv\lib\site-packages\django\template\base.py", line 500, in parse
    compile_func = self.tags[command]
KeyError: 'show_features'

During handling of the above exception, another exception occurred:

Traceback (most recent call last):
  File "D:\Desktop\flexy_tuta\flexyweb\senv\lib\site-packages\django\core\handlers\exception.py", line 47, in inner
    response = get_response(request)
  File "D:\Desktop\flexy_tuta\flexyweb\senv\lib\site-packages\django\core\handlers\base.py", line 181, in _get_response
    response = wrapped_callback(request, *callback_args, **callback_kwargs)
  File "D:\Desktop\flexy_tuta\flexyweb\pay\views.py", line 85, in payfast
    return render(request, "payment/payfast.html", context)
  File "D:\Desktop\flexy_tuta\flexyweb\senv\lib\site-packages\django\shortcuts.py", line 19, in render
    content = loader.render_to_string(template_name, context, request, using=using)
  File "D:\Desktop\flexy_tuta\flexyweb\senv\lib\site-packages\django\template\loader.py", line 61, in render_to_string
    template = get_template(template_name, using=using)
  File "D:\Desktop\flexy_tuta\flexyweb\senv\lib\site-packages\django\template\loader.py", line 15, in get_template
    return engine.get_template(template_name)
  File "D:\Desktop\flexy_tuta\flexyweb\senv\lib\site-packages\django\template\backends\django.py", line 34, in get_template
    return Template(self.engine.get_template(template_name), self)
  File "D:\Desktop\flexy_tuta\flexyweb\senv\lib\site-packages\django\template\engine.py", line 163, in get_template
    template, origin = self.find_template(template_name)
  File "D:\Desktop\flexy_tuta\flexyweb\senv\lib\site-packages\django\template\engine.py", line 145, in find_template
    template = loader.get_template(name, skip=skip)
  File "D:\Desktop\flexy_tuta\flexyweb\senv\lib\site-packages\django\template\loaders\base.py", line 29, in get_template
    return Template(
  File "D:\Desktop\flexy_tuta\flexyweb\senv\lib\site-packages\django\template\base.py", line 155, in __init__
    self.nodelist = self.compile_nodelist()
  File "D:\Desktop\flexy_tuta\flexyweb\senv\lib\site-packages\django\template\base.py", line 199, in compile_nodelist
    return parser.parse()
  File "D:\Desktop\flexy_tuta\flexyweb\senv\lib\site-packages\django\template\base.py", line 508, in parse
    raise self.error(token, e)
  File "D:\Desktop\flexy_tuta\flexyweb\senv\lib\site-packages\django\template\base.py", line 506, in parse
    compiled_result = compile_func(self, token)
  File "D:\Desktop\flexy_tuta\flexyweb\senv\lib\site-packages\django\template\loader_tags.py", line 284, in do_extends
    nodelist = parser.parse()
  File "D:\Desktop\flexy_tuta\flexyweb\senv\lib\site-packages\django\template\base.py", line 508, in parse
    raise self.error(token, e)
  File "D:\Desktop\flexy_tuta\flexyweb\senv\lib\site-packages\django\template\base.py", line 506, in parse
    compiled_result = compile_func(self, token)
  File "D:\Desktop\flexy_tuta\flexyweb\senv\lib\site-packages\django\template\loader_tags.py", line 222, in do_block
    nodelist = parser.parse(('endblock',))
  File "D:\Desktop\flexy_tuta\flexyweb\senv\lib\site-packages\django\template\base.py", line 508, in parse
    raise self.error(token, e)
  File "D:\Desktop\flexy_tuta\flexyweb\senv\lib\site-packages\django\template\base.py", line 506, in parse
    compiled_result = compile_func(self, token)
  File "D:\Desktop\flexy_tuta\flexyweb\senv\lib\site-packages\django\template\defaulttags.py", line 905, in do_if
    nodelist = parser.parse(('elif', 'else', 'endif'))
  File "D:\Desktop\flexy_tuta\flexyweb\senv\lib\site-packages\django\template\base.py", line 508, in parse
    raise self.error(token, e)
  File "D:\Desktop\flexy_tuta\flexyweb\senv\lib\site-packages\django\template\base.py", line 506, in parse
    compiled_result = compile_func(self, token)
  File "D:\Desktop\flexy_tuta\flexyweb\senv\lib\site-packages\django\template\defaulttags.py", line 810, in do_for
    nodelist_loop = parser.parse(('empty', 'endfor',))
  File "D:\Desktop\flexy_tuta\flexyweb\senv\lib\site-packages\django\template\base.py", line 502, in parse
    self.invalid_block_tag(token, command, parse_until)
  File "D:\Desktop\flexy_tuta\flexyweb\senv\lib\site-packages\django\template\base.py", line 552, in invalid_block_tag
    raise self.error(
django.template.exceptions.TemplateSyntaxError: Invalid block tag on line 88: 'show_features', expected 'empty' or 'endfor'. Did you forget to register or load this tag?
"GET /pay/payfast/ HTTP/1.1" 500 219246
Internal Server Error: /pay/payfast/
Traceback (most recent call last):
  File "D:\Desktop\flexy_tuta\flexyweb\senv\lib\site-packages\django\core\handlers\exception.py", line 47, in inner
    response = get_response(request)
  File "D:\Desktop\flexy_tuta\flexyweb\senv\lib\site-packages\django\core\handlers\base.py", line 181, in _get_response
    response = wrapped_callback(request, *callback_args, **callback_kwargs)
  File "D:\Desktop\flexy_tuta\flexyweb\pay\views.py", line 85, in payfast
    return render(request, "payment/payfast.html", context)
  File "D:\Desktop\flexy_tuta\flexyweb\senv\lib\site-packages\django\shortcuts.py", line 19, in render
    content = loader.render_to_string(template_name, context, request, using=using)
  File "D:\Desktop\flexy_tuta\flexyweb\senv\lib\site-packages\django\template\loader.py", line 62, in render_to_string
    return template.render(context, request)
  File "D:\Desktop\flexy_tuta\flexyweb\senv\lib\site-packages\django\template\backends\django.py", line 61, in render
    return self.template.render(context)
  File "D:\Desktop\flexy_tuta\flexyweb\senv\lib\site-packages\django\template\base.py", line 174, in render
    with context.bind_template(self):
  File "C:\Users\Crn96\AppData\Local\Programs\Python\Python39\lib\contextlib.py", line 117, in __enter__
    return next(self.gen)
  File "D:\Desktop\flexy_tuta\flexyweb\senv\lib\site-packages\django\template\context.py", line 244, in bind_template
    updates.update(processor(self.request))
  File "D:\Desktop\flexy_tuta\flexyweb\my_auth\context_processors.py", line 9, in show_countries
    context['payfast_merchant_id'] = config("payfast_merchant_id")
  File "D:\Desktop\flexy_tuta\flexyweb\senv\lib\site-packages\decouple.py", line 199, in __call__
    return self.config(*args, **kwargs)
  File "D:\Desktop\flexy_tuta\flexyweb\senv\lib\site-packages\decouple.py", line 83, in __call__
    return self.get(*args, **kwargs)
  File "D:\Desktop\flexy_tuta\flexyweb\senv\lib\site-packages\decouple.py", line 68, in get
    raise UndefinedValueError('{} not found. Declare it as envvar or define a default value.'.format(option))
decouple.UndefinedValueError: payfast_merchant_id not found. Declare it as envvar or define a default value.
"GET /pay/payfast/ HTTP/1.1" 500 117378
Internal Server Error: /pay/payfast/
Traceback (most recent call last):
  File "D:\Desktop\flexy_tuta\flexyweb\senv\lib\site-packages\django\core\handlers\exception.py", line 47, in inner
    response = get_response(request)
  File "D:\Desktop\flexy_tuta\flexyweb\senv\lib\site-packages\django\core\handlers\base.py", line 181, in _get_response
    response = wrapped_callback(request, *callback_args, **callback_kwargs)
  File "D:\Desktop\flexy_tuta\flexyweb\pay\views.py", line 87, in payfast
    order = Order.objects.get(id=id)
  File "D:\Desktop\flexy_tuta\flexyweb\senv\lib\site-packages\django\db\models\manager.py", line 85, in manager_method
    return getattr(self.get_queryset(), name)(*args, **kwargs)
  File "D:\Desktop\flexy_tuta\flexyweb\senv\lib\site-packages\django\db\models\query.py", line 439, in get
    raise self.model.DoesNotExist(
panel.models.Order.DoesNotExist: Order matching query does not exist.
"GET /pay/payfast/ HTTP/1.1" 500 82959
Internal Server Error: /pay/reciept/order/46/pdf/
Traceback (most recent call last):
  File "D:\Desktop\flexy_tuta\flexyweb\senv\lib\site-packages\django\core\handlers\exception.py", line 47, in inner
    response = get_response(request)
  File "D:\Desktop\flexy_tuta\flexyweb\senv\lib\site-packages\django\core\handlers\base.py", line 181, in _get_response
    response = wrapped_callback(request, *callback_args, **callback_kwargs)
  File "D:\Desktop\flexy_tuta\flexyweb\pay\views.py", line 277, in invoice_order_detail
    stylesheets=[weasyprint.CSS(settings.STATIC_ROOT + '/css/template.css')])
  File "D:\Desktop\flexy_tuta\flexyweb\senv\lib\site-packages\weasyprint\__init__.py", line 322, in __init__
    with result as (source_type, source, base_url, protocol_encoding):
  File "C:\Users\Crn96\AppData\Local\Programs\Python\Python39\lib\contextlib.py", line 117, in __enter__
    return next(self.gen)
  File "D:\Desktop\flexy_tuta\flexyweb\senv\lib\site-packages\weasyprint\__init__.py", line 396, in _select_source
    with result as result:
  File "C:\Users\Crn96\AppData\Local\Programs\Python\Python39\lib\contextlib.py", line 117, in __enter__
    return next(self.gen)
  File "D:\Desktop\flexy_tuta\flexyweb\senv\lib\site-packages\weasyprint\__init__.py", line 403, in _select_source
    with open(filename, 'rb') as file_obj:
FileNotFoundError: [Errno 2] No such file or directory: 'D:\\Desktop\\flexy_tuta\\flexyweb\\static/css/template.css'
"GET /pay/reciept/order/46/pdf/ HTTP/1.1" 500 101775
Internal Server Error: /contact/
Traceback (most recent call last):
  File "D:\Desktop\flexy_tuta\flexyweb\senv\lib\site-packages\django\core\handlers\exception.py", line 47, in inner
    response = get_response(request)
  File "D:\Desktop\flexy_tuta\flexyweb\senv\lib\site-packages\django\core\handlers\base.py", line 181, in _get_response
    response = wrapped_callback(request, *callback_args, **callback_kwargs)
  File "D:\Desktop\flexy_tuta\flexyweb\contact\views.py", line 95, in contact
    msg.send()
  File "D:\Desktop\flexy_tuta\flexyweb\senv\lib\site-packages\django\core\mail\message.py", line 284, in send
    return self.get_connection(fail_silently).send_messages([self])
  File "D:\Desktop\flexy_tuta\flexyweb\senv\lib\site-packages\django\core\mail\backends\smtp.py", line 102, in send_messages
    new_conn_created = self.open()
  File "D:\Desktop\flexy_tuta\flexyweb\senv\lib\site-packages\django\core\mail\backends\smtp.py", line 69, in open
    self.connection.login(self.username, self.password)
  File "C:\Users\Crn96\AppData\Local\Programs\Python\Python39\lib\smtplib.py", line 723, in login
    (code, resp) = self.auth(
  File "C:\Users\Crn96\AppData\Local\Programs\Python\Python39\lib\smtplib.py", line 635, in auth
    (code, resp) = self.docmd("AUTH", mechanism + " " + response)
  File "C:\Users\Crn96\AppData\Local\Programs\Python\Python39\lib\smtplib.py", line 425, in docmd
    return self.getreply()
  File "C:\Users\Crn96\AppData\Local\Programs\Python\Python39\lib\smtplib.py", line 398, in getreply
    raise SMTPServerDisconnected("Connection unexpectedly closed")
smtplib.SMTPServerDisconnected: Connection unexpectedly closed
"POST /contact/ HTTP/1.1" 500 113473
Internal Server Error: /password_reset/
Traceback (most recent call last):
  File "D:\Desktop\flexy_tuta\flexyweb\senv\lib\site-packages\django\core\handlers\exception.py", line 47, in inner
    response = get_response(request)
  File "D:\Desktop\flexy_tuta\flexyweb\senv\lib\site-packages\django\core\handlers\base.py", line 181, in _get_response
    response = wrapped_callback(request, *callback_args, **callback_kwargs)
  File "D:\Desktop\flexy_tuta\flexyweb\my_auth\views.py", line 63, in password_reset_request
    msg.send()
  File "D:\Desktop\flexy_tuta\flexyweb\senv\lib\site-packages\django\core\mail\message.py", line 284, in send
    return self.get_connection(fail_silently).send_messages([self])
  File "D:\Desktop\flexy_tuta\flexyweb\senv\lib\site-packages\django\core\mail\backends\smtp.py", line 102, in send_messages
    new_conn_created = self.open()
  File "D:\Desktop\flexy_tuta\flexyweb\senv\lib\site-packages\django\core\mail\backends\smtp.py", line 69, in open
    self.connection.login(self.username, self.password)
  File "C:\Users\Crn96\AppData\Local\Programs\Python\Python39\lib\smtplib.py", line 723, in login
    (code, resp) = self.auth(
  File "C:\Users\Crn96\AppData\Local\Programs\Python\Python39\lib\smtplib.py", line 635, in auth
    (code, resp) = self.docmd("AUTH", mechanism + " " + response)
  File "C:\Users\Crn96\AppData\Local\Programs\Python\Python39\lib\smtplib.py", line 425, in docmd
    return self.getreply()
  File "C:\Users\Crn96\AppData\Local\Programs\Python\Python39\lib\smtplib.py", line 398, in getreply
    raise SMTPServerDisconnected("Connection unexpectedly closed")
smtplib.SMTPServerDisconnected: Connection unexpectedly closed
"POST /password_reset/ HTTP/1.1" 500 113546
Internal Server Error: /apply/user-info-3/
Traceback (most recent call last):
  File "D:\Desktop\flexy_tuta\flexyweb\senv\lib\site-packages\django\core\handlers\exception.py", line 47, in inner
    response = get_response(request)
  File "D:\Desktop\flexy_tuta\flexyweb\senv\lib\site-packages\django\core\handlers\base.py", line 181, in _get_response
    response = wrapped_callback(request, *callback_args, **callback_kwargs)
  File "D:\Desktop\flexy_tuta\flexyweb\panel\views.py", line 80, in apply3
    return render(request, "apply/apply3.html", context)
  File "D:\Desktop\flexy_tuta\flexyweb\senv\lib\site-packages\django\shortcuts.py", line 19, in render
    content = loader.render_to_string(template_name, context, request, using=using)
  File "D:\Desktop\flexy_tuta\flexyweb\senv\lib\site-packages\django\template\loader.py", line 62, in render_to_string
    return template.render(context, request)
  File "D:\Desktop\flexy_tuta\flexyweb\senv\lib\site-packages\django\template\backends\django.py", line 61, in render
    return self.template.render(context)
  File "D:\Desktop\flexy_tuta\flexyweb\senv\lib\site-packages\django\template\base.py", line 174, in render
    with context.bind_template(self):
  File "C:\Users\Crn96\AppData\Local\Programs\Python\Python39\lib\contextlib.py", line 117, in __enter__
    return next(self.gen)
  File "D:\Desktop\flexy_tuta\flexyweb\senv\lib\site-packages\django\template\context.py", line 244, in bind_template
    updates.update(processor(self.request))
  File "D:\Desktop\flexy_tuta\flexyweb\cart\context_processors.py", line 43, in show_me
    total = total + value_added_tax
TypeError: unsupported operand type(s) for +: 'decimal.Decimal' and 'float'
"GET /apply/user-info-3/ HTTP/1.1" 500 107785
Internal Server Error: /apply/user-info-3/
Traceback (most recent call last):
  File "D:\Desktop\flexy_tuta\flexyweb\senv\lib\site-packages\django\core\handlers\exception.py", line 47, in inner
    response = get_response(request)
  File "D:\Desktop\flexy_tuta\flexyweb\senv\lib\site-packages\django\core\handlers\base.py", line 181, in _get_response
    response = wrapped_callback(request, *callback_args, **callback_kwargs)
  File "D:\Desktop\flexy_tuta\flexyweb\panel\views.py", line 80, in apply3
    return render(request, "apply/apply3.html", context)
  File "D:\Desktop\flexy_tuta\flexyweb\senv\lib\site-packages\django\shortcuts.py", line 19, in render
    content = loader.render_to_string(template_name, context, request, using=using)
  File "D:\Desktop\flexy_tuta\flexyweb\senv\lib\site-packages\django\template\loader.py", line 62, in render_to_string
    return template.render(context, request)
  File "D:\Desktop\flexy_tuta\flexyweb\senv\lib\site-packages\django\template\backends\django.py", line 61, in render
    return self.template.render(context)
  File "D:\Desktop\flexy_tuta\flexyweb\senv\lib\site-packages\django\template\base.py", line 174, in render
    with context.bind_template(self):
  File "C:\Users\Crn96\AppData\Local\Programs\Python\Python39\lib\contextlib.py", line 117, in __enter__
    return next(self.gen)
  File "D:\Desktop\flexy_tuta\flexyweb\senv\lib\site-packages\django\template\context.py", line 244, in bind_template
    updates.update(processor(self.request))
  File "D:\Desktop\flexy_tuta\flexyweb\cart\context_processors.py", line 43, in show_me
    total = total + float(value_added_tax)
TypeError: unsupported operand type(s) for +: 'decimal.Decimal' and 'float'
"GET /apply/user-info-3/ HTTP/1.1" 500 108193
Internal Server Error: /pay/payfast/
Traceback (most recent call last):
  File "D:\Desktop\flexy_tuta\flexyweb\senv\lib\site-packages\django\core\handlers\exception.py", line 47, in inner
    response = get_response(request)
  File "D:\Desktop\flexy_tuta\flexyweb\senv\lib\site-packages\django\core\handlers\base.py", line 181, in _get_response
    response = wrapped_callback(request, *callback_args, **callback_kwargs)
  File "D:\Desktop\flexy_tuta\flexyweb\pay\views.py", line 87, in payfast
    order = Order.objects.get(id=id)
  File "D:\Desktop\flexy_tuta\flexyweb\senv\lib\site-packages\django\db\models\manager.py", line 85, in manager_method
    return getattr(self.get_queryset(), name)(*args, **kwargs)
  File "D:\Desktop\flexy_tuta\flexyweb\senv\lib\site-packages\django\db\models\query.py", line 439, in get
    raise self.model.DoesNotExist(
panel.models.Order.DoesNotExist: Order matching query does not exist.
"GET /pay/payfast/ HTTP/1.1" 500 82947
Internal Server Error: /contact/
Traceback (most recent call last):
  File "D:\Desktop\flexy_tuta\flexyweb\senv\lib\site-packages\django\core\handlers\exception.py", line 47, in inner
    response = get_response(request)
  File "D:\Desktop\flexy_tuta\flexyweb\senv\lib\site-packages\django\core\handlers\base.py", line 181, in _get_response
    response = wrapped_callback(request, *callback_args, **callback_kwargs)
  File "D:\Desktop\flexy_tuta\flexyweb\contact\views.py", line 95, in contact
    msg.send()
  File "D:\Desktop\flexy_tuta\flexyweb\senv\lib\site-packages\django\core\mail\message.py", line 284, in send
    return self.get_connection(fail_silently).send_messages([self])
  File "D:\Desktop\flexy_tuta\flexyweb\senv\lib\site-packages\django\core\mail\backends\smtp.py", line 102, in send_messages
    new_conn_created = self.open()
  File "D:\Desktop\flexy_tuta\flexyweb\senv\lib\site-packages\django\core\mail\backends\smtp.py", line 62, in open
    self.connection = self.connection_class(self.host, self.port, **connection_params)
  File "C:\Users\Crn96\AppData\Local\Programs\Python\Python39\lib\smtplib.py", line 1034, in __init__
    SMTP.__init__(self, host, port, local_hostname, timeout,
  File "C:\Users\Crn96\AppData\Local\Programs\Python\Python39\lib\smtplib.py", line 253, in __init__
    (code, msg) = self.connect(host, port)
  File "C:\Users\Crn96\AppData\Local\Programs\Python\Python39\lib\smtplib.py", line 339, in connect
    self.sock = self._get_socket(host, port, self.timeout)
  File "C:\Users\Crn96\AppData\Local\Programs\Python\Python39\lib\smtplib.py", line 1040, in _get_socket
    new_socket = super()._get_socket(host, port, timeout)
  File "C:\Users\Crn96\AppData\Local\Programs\Python\Python39\lib\smtplib.py", line 310, in _get_socket
    return socket.create_connection((host, port), timeout,
  File "C:\Users\Crn96\AppData\Local\Programs\Python\Python39\lib\socket.py", line 843, in create_connection
    raise err
  File "C:\Users\Crn96\AppData\Local\Programs\Python\Python39\lib\socket.py", line 831, in create_connection
    sock.connect(sa)
TimeoutError: [WinError 10060] A connection attempt failed because the connected party did not properly respond after a period of time, or established connection failed because connected host has failed to respond
